Workbook
Name _0_ICQ_ConstInd: #REF!
Name _0_ICQ_Contingency: #REF!
Name _0_ICQ_Engineering: #REF!
Name _0_ICQ_FldOfcInd: #REF!
Name _0_ICQ_Freight: #REF!
Name _0_ICQ_OtherProjCosts: #REF!
Name _0_ICQ_TaxesPermits: #REF!
Name _0_SLQ_MetricsDIR: #REF!
Name _0_SLQ_MetricsIND: #REF!
Name _0_TAQ_TDC_AcctSumry: #REF!
Name _0_TAQ_TDC_COASumry: '[2]TDC COA Sumry'!$A$6
Name _0_TAQ_TDC_ItemDetsByOrigin: '[2]TDC Item Dets'!$A$6
Name _0_TAQ_TDC_ItemSumry: #REF!
Name _0_TAQ_TDC_KeyQtySumry: '[2]TDC Key Qty Sumry'!$A$6
Name _3_AQ_Acct3Pipe_AvgDiam: #REF!
Name _3_AQ_AGPipe_AvgDiam: #REF!
Name _3_AQ_AGPipe_AvgDiam_BoreLg: #REF!
Name _3_AQ_AGPipe_AvgDiam_BoreSm: #REF!
Name _3_AQ_AGPipe_AvgDiam_MatCS: #REF!
Name _3_AQ_AGPipe_AvgDiam_MatMisc: #REF!
Name _3_AQ_AGPipe_AvgDiam_MatSS: #REF!
Name _3_AQ_UGPipe_AvgDiam: #REF!
Name _3_KQQ_AGPipe_Sub1_BoreLg: #REF!
Name _3_KQQ_AGPipe_Sub1_BoreSm: #REF!
Name _3_KQQ_AGPipe_Sub2_InstPipe: #REF!
Name _3_KQQ_AGPipe_Sub2_Spool: #REF!
Name _3_KQQ_AGPipe_Sub2_StRun: #REF!
Name _3_KQQ_AGPipe_Sub3_FieldRunFab: #REF!
Name _3_KQQ_AGPipe_Sub3_RemoteFab: #REF!
Name _3_KQQ_AGPipeLength_MatCS: #REF!
Name _3_KQQ_AGPipeLength_MatMisc: #REF!
Name _3_KQQ_AGPipeLength_MatSS: #REF!
Name _4_KQQ_Conc_Sub1_BlkLg: #REF!
Name _4_KQQ_Conc_Sub1_BlkMed: #REF!
Name _4_KQQ_Conc_Sub1_BlkSm: #REF!
Name _4_KQQ_Conc_Sub1_DuctBank: #REF!
Name _4_KQQ_Conc_Sub1_Elev: #REF!
Name _4_KQQ_Conc_Sub1_MassLg: #REF!
Name _4_KQQ_Conc_Sub1_MassMed: #REF!
Name _4_KQQ_Conc_Sub1_MassSm: #REF!
Name _4_KQQ_Conc_Sub1_Piling: #REF!
Name _4_KQQ_ConcTot_Embeds: #REF!
Name _4_KQQ_ConcTot_ExcBF: #REF!
Name _4_KQQ_ConcTot_Forms: #REF!
Name _4_KQQ_ConcTot_Grout: #REF!
Name _4_KQQ_ConcTot_Rebar: #REF!
Name _4_KQQ_ConcTotQty: #REF!
Name _5_KQQ_TotQty_Sub1_ExLtLt: #REF!
Name _5_KQQ_TotQty_Sub1_HvyXHvy: #REF!
Name _5_KQQ_TotQty_Sub1_Ldr: #REF!
Name _5_KQQ_TotQty_Sub1_Med: #REF!
Name _5_KQQ_TotQty_Sub1_Misc: #REF!
Name _5_KQQ_TotQty_Sub1_PlatStrGrt: #REF!
Name _5_KQQ_TotQty_Sub2_FloorTread: #REF!
Name _5_KQQ_TotQty_Sub2_HR: #REF!
Name _5_KQQ_TotQty_Sub2_Ladder: #REF!
Name _5_KQQ_TotQty_Sub2_Other: #REF!
Name _5_KQQ_TotQty_Sub2_Piperack: #REF!
Name _5_KQQ_TotQty_Sub2_Platform: #REF!
Name _5_KQQ_TotQty_Sub2_Structure: #REF!

Sheet Material Procurement
C2: Cost (USD)
A3: Phase 1: Send to Africa | B3: Required
A4: 360 miners (from Richard) | B4: 360 | C4: =B4*400 -> 144000
A5: 1 TON Infraflow (from Richard) | B5: 1 | C5: 80000
A6: 1 Transformer from China | B6: 1 | C6: 30000
A7: Cable from Nigeria | C7: 12000
A8: Auxilary
A9: 1 Dorm container (From TON yard) | B9: 1 | C9: TBD
B10: Total | C10: =SUM(C4:C9) -> 266000
A11: Phase 2: Send to Africa | B11: Required
A12: 1080 miners (from Richard) | B12: 1080 | C12: =B12*400 -> 432000
A13: From TON yard
A14: Other
A15: 3 TON Infraflow (from Richard) | B15: 3 | C15: 160000
A16: 3 Transformer from Nigeria | B16: 3 | C16: 60000
A17: Cable from Nigeria (or maybe ship from Texas) | C17: 24000
A18: Auxilary
B19: Total | C19: =SUM(C12:C18) -> 676000

Sheet Axxela 10MW - BTC model
A1: Axxela 10MW Project Model Overview
A5: Assumed BTCUSD
A6: 80000
A8: Genset Cost Each | B8: 700000
A9: Container Cost Each | B9: 115000
A10: Buildout Cost Each | B10: 20000 | C10: TH | D10: W
A11: Miners | B11: 800 | C11: 120 | D11: 3250 | AJ11: Miners | AK11: 800 | AL11: 200 | AM11: 3600
A12: Operations | B12: 875 | AJ12: Halvening
B13: 45839 | C13: 45870 | D13: 45901 | E13: 45931 | F13: 45962 | G13: 45992 | H13: 46023 | I13: 46054 | J13: 46082 | K13: 46113 | L13: 46143 | M13: 46174 | N13: 46204 | P13: 46235 | Q13: 46266 | R13: 46296 | S13: 46327 | T13: 46357 | U13: 46388 | V13: 46419 | W13: 46447 | X13: 46478 | Y13: 46508 | Z13: 46539 | AA13: 46569 | AB13: 46600 | AD13: 46631 | AE13: 46661 | AF13: 46692 | AG13: 46722 | AH13: 46753 | AI13: 46784 | AJ13: 46813 | AK13: 46844 | AL13: 46874 | AM13: 46905 | AN13: 46935 | AO13: 46966 | AP13: 46997
A14: New Infrastructure count | B14: Month 0 | C14: Month 1 | D14: Month 2 | E14: Month 3 | F14: Month 4 | G14: Month 5 | H14: Month 6 | I14: Month 7 | J14: Month 8 | K14: Month 9 | L14: Month 10 | M14: Month 11 | N14: Month 12 | O14: Year1 | P14: Month 0 | Q14: Month 1 | R14: Month 2 | S14: Month 3 | T14: Month 4 | U14: Month 5 | V14: Month 6 | W14: Month 7 | X14: Month 8 | Y14: Month 9 | Z14: Month 10 | AA14: Month 11 | AB14: Month 12 | AC14: Year1 | AD14: Month 0 | AE14: Month 1 | AF14: Month 2 | AG14: Month 3 | AH14: Month 4 | AI14: Month 5 | AJ14: Month 6 | AK14: Month 7 | AL14: Month 8 | AM14: Month 9 | AN14: Month 10 | AO14: Month 11 | AP14: Month 12 | AQ14: Year1
A15: New Containers | B15: 1 | C15: 1 | D15: 1 | E15: 1 | F15: 1 | G15: 1 | H15: 1 | I15: 1
A16: New miners | B16: 360 | C16: 360 | D16: 360 | E16: 360 | F16: 360 | G16: 360 | H16: 360 | I16: 360 | AJ16: 2600
A17: New Gensets | B17: 1 | C17: 1 | D17: 1 | E17: 1 | F17: 1 | G17: 1 | H17: 1 | I17: 1
A18: Total Infrastructure Count | B18: Month 0 | C18: Month 1 | D18: Month 2 | E18: Month 3 | F18: Month 4 | G18: Month 5 | H18: Month 6 | I18: Month 7 | J18: Month 8 | K18: Month 9 | L18: Month 10 | M18: Month 11 | N18: Month 12 | P18: Month 0 | Q18: Month 1 | R18: Month 2 | S18: Month 3 | T18: Month 4 | U18: Month 5 | V18: Month 6 | W18: Month 7 | X18: Month 8 | Y18: Month 9 | Z18: Month 10 | AA18: Month 11 | AB18: Month 12 | AD18: Month 0 | AE18: Month 1 | AF18: Month 2 | AG18: Month 3 | AH18: Month 4 | AI18: Month 5 | AJ18: Month 6 | AK18: Month 7 | AL18: Month 8 | AM18: Month 9 | AN18: Month 10 | AO18: Month 11 | AP18: Month 12
A19: Containers | B19: 1 | C19: 2 | D19: 3 | E19: 4 | F19: 5 | G19: 6 | H19: 7 | I19: 8 | J19: 8 | K19: 8 | L19: 8 | M19: 8 | N19: 8 | P19: 8 | Q19: 8 | R19: 8 | S19: 8 | T19: 8 | U19: 8 | V19: 8 | W19: 8 | X19: 8 | Y19: 8 | Z19: 8 | AA19: 8 | AB19: 8 | AD19: 8 | AE19: 8 | AF19: 8 | AG19: 8 | AH19: 8 | AI19: 8 | AJ19: 8 | AK19: 8 | AL19: 8 | AM19: 8 | AN19: 8 | AO19: 8 | AP19: 8
A20: Miners Total | B20: 360 | C20: 720 | D20: 1080 | E20: 1440 | F20: 1800 | G20: 2160 | H20: 2520 | I20: 2880 | J20: 2880 | K20: 2880 | L20: 2880 | M20: 2880 | N20: 2880 | P20: 2880 | Q20: 2880 | R20: 2880 | S20: 2880 | T20: 2880 | U20: 2880 | V20: 2880 | W20: 2880 | X20: 2880 | Y20: 2880 | Z20: 2880 | AA20: 2880 | AB20: 2880 | AD20: 2880 | AE20: 2880 | AF20: 2880 | AG20: 2880 | AH20: 2880 | AI20: 2880 | AJ20: 2600 | AK20: 2600 | AL20: 2600 | AM20: 2600 | AN20: 2600 | AO20: 2600 | AP20: 2600
A21: Gensets Total | B21: 1 | C21: 2 | D21: 3 | E21: 4 | F21: 5 | G21: 6 | H21: 7 | I21: 8 | J21: 8 | K21: 8 | L21: 8 | M21: 8 | N21: 8 | P21: 8 | Q21: 8 | R21: 8 | S21: 8 | T21: 8 | U21: 8 | V21: 8 | W21: 8 | X21: 8 | Y21: 8 | Z21: 8 | AA21: 8 | AB21: 8 | AD21: 8 | AE21: 8 | AF21: 8 | AG21: 8 | AH21: 8 | AI21: 8 | AJ21: 8 | AK21: 8 | AL21: 8 | AM21: 8 | AN21: 8 | AO21: 8 | AP21: 8
A22: Site Power (MW) | B22: 1.17 | C22: 2.34 | D22: 3.51 | E22: 4.68 | F22: 5.85 | G22: 7.02 | H22: 8.19 | I22: 9.36 | J22: 9.36 | K22: 9.36 | L22: 9.36 | M22: 9.36 | N22: 9.36 | P22: 9.36 | Q22: 9.36 | R22: 9.36 | S22: 9.36 | T22: 9.36 | U22: 9.36 | V22: 9.36 | W22: 9.36 | X22: 9.36 | Y22: 9.36 | Z22: 9.36 | AA22: 9.36 | AB22: 9.36 | AD22: 9.36 | AE22: 9.36 | AF22: 9.36 | AG22: 9.36 | AH22: 9.36 | AI22: 9.36 | AJ22: 8.45 | AK22: 8.45 | AL22: 8.45 | AM22: 8.45 | AN22: 8.45 | AO22: 8.45 | AP22: 8.45
A23: Hashing Online Total Site (PH) | B23: 43.2 | C23: 86.4 | D23: 129.6 | E23: 172.8 | F23: 216 | G23: 259.2 | H23: 302.4 | I23: 345.6 | J23: 345.6 | K23: 345.6 | L23: 345.6 | M23: 345.6 | N23: 345.6 | P23: 345.6 | Q23: 345.6 | R23: 345.6 | S23: 345.6 | T23: 345.6 | U23: 345.6 | V23: 345.6 | W23: 345.6 | X23: 345.6 | Y23: 345.6 | Z23: 345.6 | AA23: 345.6 | AB23: 345.6 | AD23: 345.6 | AE23: 345.6 | AF23: 345.6 | AG23: 345.6 | AH23: 345.6 | AI23: 345.6 | AJ23: 312 | AK23: 312 | AL23: 312 | AM23: 312 | AN23: 312 | AO23: 312 | AP23: 312
A24: Hashing Online TON (TH) | B24: 43200 | C24: 86400 | D24: 129600 | E24: 172800 | F24: 216000 | G24: 259200 | H24: 302400 | I24: 345600 | J24: 345600 | K24: 345600 | L24: 345600 | M24: 345600 | N24: 345600 | P24: 345600 | Q24: 345600 | R24: 345600 | S24: 345600 | T24: 345600 | U24: 345600 | V24: 345600 | W24: 345600 | X24: 345600 | Y24: 345600 | Z24: 345600 | AA24: 345600 | AB24: 345600 | AD24: 345600 | AE24: 345600 | AF24: 345600 | AG24: 345600 | AH24: 345600 | AI24: 345600 | AJ24: 520000 | AK24: 520000 | AL24: 520000 | AM24: 520000 | AN24: 520000 | AO24: 520000 | AP24: 520000
A26: Cashflow | B26: Month 0 | C26: Month 1 | D26: Month 2 | E26: Month 3 | F26: Month 4 | G26: Month 5 | H26: Month 6 | I26: Month 7 | J26: Month 8 | K26: Month 9 | L26: Month 10 | M26: Month 11 | N26: Month 12 | P26: Month 0 | Q26: Month 1 | R26: Month 2 | S26: Month 3 | T26: Month 4 | U26: Month 5 | V26: Month 6 | W26: Month 7 | X26: Month 8 | Y26: Month 9 | Z26: Month 10 | AA26: Month 11 | AB26: Month 12 | AD26: Month 0 | AE26: Month 1 | AF26: Month 2 | AG26: Month 3 | AH26: Month 4 | AI26: Month 5 | AJ26: Month 6 | AK26: Month 7 | AL26: Month 8 | AM26: Month 9 | AN26: Month 10 | AO26: Month 11 | AP26: Month 12
A27: Costs
A28: Axxela Capex
A29: Gensets | B29: 700000 | C29: 700000 | D29: 700000 | E29: 700000 | F29: 700000 | G29: 700000 | H29: 700000 | I29: 700000 | O29: 5600000
A30: TON Capex
A31: Container | B31: 95000 | C31: 95000 | D31: 95000 | E31: 95000 | F31: 95000 | G31: 95000 | H31: 95000 | I31: 95000 | J31: 0 | K31: 0 | L31: 0 | M31: 0 | N31: 0 | P31: 0 | Q31: 0 | R31: 0 | S31: 0 | T31: 0 | U31: 0 | V31: 0 | W31: 0 | X31: 0 | Y31: 0 | Z31: 0 | AA31: 0 | AB31: 0 | AD31: 0 | AE31: 0 | AF31: 0 | AG31: 0 | AH31: 0 | AI31: 0 | AJ31: 0 | AK31: 0 | AL31: 0 | AM31: 0 | AN31: 0 | AO31: 0 | AP31: 0 | AQ31: 0
A32: Miners | B32: 288000 | C32: 288000 | D32: 288000 | E32: 288000 | F32: 288000 | G32: 288000 | H32: 288000 | I32: 288000 | J32: 0 | K32: 0 | L32: 0 | M32: 0 | N32: 0 | P32: 0 | Q32: 0 | R32: 0 | S32: 0 | T32: 0 | U32: 0 | V32: 0 | W32: 0 | X32: 0 | Y32: 0 | Z32: 0 | AA32: 0 | AB32: 0 | AD32: 0 | AE32: 0 | AF32: 0 | AG32: 0 | AH32: 0 | AI32: 0 | AJ32: 1852795.5 | AK32: 0 | AL32: 0 | AM32: 0 | AN32: 0 | AO32: 0 | AP32: 0 | AQ32: 1852795.5
A33: Construction | B33: 20000 | C33: 20000 | D33: 20000 | E33: 20000 | F33: 20000 | G33: 20000 | H33: 20000 | I33: 20000 | J33: 0 | K33: 0 | L33: 0 | M33: 0 | N33: 0 | P33: 0 | Q33: 0 | R33: 0 | S33: 0 | T33: 0 | U33: 0 | V33: 0 | W33: 0 | X33: 0 | Y33: 0 | Z33: 0 | AA33: 0 | AB33: 0 | AD33: 0 | AE33: 0 | AF33: 0 | AG33: 0 | AH33: 0 | AI33: 0 | AJ33: 0 | AK33: 0 | AL33: 0 | AM33: 0 | AN33: 0 | AO33: 0 | AP33: 0 | AQ33: 0
A34: Site Development Management | B34: 10000 | C34: 10000 | D34: 10000 | E34: 10000 | F34: 10000 | G34: 10000 | H34: 10000 | I34: 10000 | J34: 0 | K34: 0 | L34: 0 | M34: 0 | N34: 0 | P34: 0 | Q34: 0 | R34: 0 | S34: 0 | T34: 0 | U34: 0 | V34: 0 | W34: 0 | X34: 0 | Y34: 0 | Z34: 0 | AA34: 0 | AB34: 0 | AD34: 0 | AE34: 0 | AF34: 0 | AG34: 0 | AH34: 0 | AI34: 0 | AJ34: 0 | AK34: 0 | AL34: 0 | AM34: 0 | AN34: 0 | AO34: 0 | AP34: 0 | AQ34: 0
A35: Africa Customs and Logistics | B35: 16600 | C35: 16600 | D35: 16600 | E35: 16600 | F35: 16600 | G35: 16600 | H35: 16600 | I35: 16600 | J35: 0 | K35: 0 | L35: 0 | M35: 0 | N35: 0 | P35: 0 | Q35: 0 | R35: 0 | S35: 0 | T35: 0 | U35: 0 | V35: 0 | W35: 0 | X35: 0 | Y35: 0 | Z35: 0 | AA35: 0 | AB35: 0 | AD35: 0 | AE35: 0 | AF35: 0 | AG35: 0 | AH35: 0 | AI35: 0 | AJ35: 0 | AK35: 0 | AL35: 0 | AM35: 0 | AN35: 0 | AO35: 0 | AP35: 0
A36: CapEx Total | B36: 429600 | C36: 429600 | D36: 429600 | E36: 429600 | F36: 429600 | G36: 429600 | H36: 429600 | I36: 429600 | J36: 0 | K36: 0 | L36: 0 | M36: 0 | N36: 0 | O36: 3436800 | P36: 0 | Q36: 0 | R36: 0 | S36: 0 | T36: 0 | U36: 0 | V36: 0 | W36: 0 | X36: 0 | Y36: 0 | Z36: 0 | AA36: 0 | AB36: 0 | AD36: 0 | AE36: 0 | AF36: 0 | AG36: 0 | AH36: 0 | AI36: 0 | AJ36: 1852795.5 | AK36: 0 | AL36: 0 | AM36: 0 | AN36: 0 | AO36: 0 | AP36: 0 | AQ36: 1852795.5
A38: OpEx
A39: Site Operations | B39: 875 | C39: 1750 | D39: 2625 | E39: 3500 | F39: 4375 | G39: 5250 | H39: 6125 | I39: 7000 | J39: 7000 | K39: 7000 | L39: 7000 | M39: 7000 | N39: 7000 | P39: 7000 | Q39: 7000 | R39: 7000 | S39: 7000 | T39: 7000 | U39: 7000 | V39: 7000 | W39: 7000 | X39: 7000 | Y39: 7000 | Z39: 7000 | AA39: 7000 | AB39: 7000 | AD39: 7000 | AE39: 7000 | AF39: 7000 | AG39: 7000 | AH39: 7000 | AI39: 7000 | AJ39: 7000 | AK39: 7000 | AL39: 7000 | AM39: 7000 | AN39: 7000 | AO39: 7000 | AP39: 7000
A40: OpEx Total | B40: 875 | C40: 1750 | D40: 2625 | E40: 3500 | F40: 4375 | G40: 5250 | H40: 6125 | I40: 7000 | J40: 7000 | K40: 7000 | L40: 7000 | M40: 7000 | N40: 7000 | P40: 7000 | Q40: 7000 | R40: 7000 | S40: 7000 | T40: 7000 | U40: 7000 | V40: 7000 | W40: 7000 | X40: 7000 | Y40: 7000 | Z40: 7000 | AA40: 7000 | AB40: 7000 | AD40: 7000 | AE40: 7000 | AF40: 7000 | AG40: 7000 | AH40: 7000 | AI40: 7000 | AJ40: 7000 | AK40: 7000 | AL40: 7000 | AM40: 7000 | AN40: 7000 | AO40: 7000 | AP40: 7000
A41: Revenue | B41: Month 0 | C41: Month 1 | D41: Month 2 | E41: Month 3 | F41: Month 4 | G41: Month 5 | H41: Month 6 | I41: Month 7 | J41: Month 8 | K41: Month 9 | L41: Month 10 | M41: Month 11 | N41: Month 12 | O41: Year 1 | P41: Month 0 | Q41: Month 1 | R41: Month 2 | S41: Month 3 | T41: Month 4 | U41: Month 5 | V41: Month 6 | W41: Month 7 | X41: Month 8 | Y41: Month 9 | Z41: Month 10 | AA41: Month 11 | AB41: Month 12 | AC41: Year 1 | AD41: Month 0 | AE41: Month 1 | AF41: Month 2 | AG41: Month 3 | AH41: Month 4 | AI41: Month 5 | AJ41: Month 6 | AK41: Month 7 | AL41: Month 8 | AM41: Month 9 | AN41: Month 10 | AO41: Month 11 | AP41: Month 12 | AQ41: Year 1
A42: Mining Difficulty (T) | B42: 120 | C42: 123.11458 | D42: 126.31 | E42: 129.58835 | F42: 132.9518 | G42: 136.40254 | H42: 139.94285 | I42: 143.57504 | J42: 147.30151 | K42: 151.12469 | L42: 155.04711 | M42: 159.07133 | N42: 163.2 | P42: 167.43583 | Q42: 171.7816 | R42: 176.24016 | S42: 180.81445 | T42: 185.50745 | U42: 190.32227 | V42: 195.26205 | W42: 200.33005 | X42: 205.52958 | Y42: 210.86407 | Z42: 216.33701 | AA42: 221.952 | AB42: 227.71273 | AD42: 233.62297 | AE42: 239.68662 | AF42: 245.90765 | AG42: 252.29014 | AH42: 258.83829 | AI42: 265.55639 | AJ42: 272.44886 | AK42: 279.52023 | AL42: 286.77513 | AM42: 294.21833 | AN42: 301.85472 | AO42: 309.68931 | AP42: 317.72724
A43: Forecasted Bitcoin Value (USD) | B43: 80000 | C43: 81501.541 | D43: 83031.265 | E43: 84589.701 | F43: 86177.388 | G43: 87794.874 | H43: 89442.719 | I43: 91121.493 | J43: 92831.777 | K43: 94574.161 | L43: 96349.248 | M43: 98157.653 | N43: 100000 | P43: 101876.93 | Q43: 103789.08 | R43: 105737.13 | S43: 107721.73 | T43: 109743.59 | U43: 111803.4 | V43: 113901.87 | W43: 116039.72 | X43: 118217.7 | Y43: 120436.56 | Z43: 122697.07 | AA43: 125000 | AB43: 127346.16 | AD43: 129736.35 | AE43: 132171.41 | AF43: 134652.17 | AG43: 137179.49 | AH43: 139754.25 | AI43: 142377.33 | AJ43: 145049.65 | AK43: 147772.13 | AL43: 150545.7 | AM43: 153371.33 | AN43: 156250 | AO43: 159182.7 | AP43: 162170.44
A44: Bitcoin per month | C44: 1.3235167 | D44: 1.9350511 | E44: 2.5147969 | F44: 3.0639713 | G44: 3.5837499 | H44: 4.0752687 | I44: 4.5396247 | J44: 4.4247802 | K44: 4.3128412 | L44: 4.2037339 | M44: 4.0973869 | N44: 3.9937303 | P44: 3.8926961 | Q44: 3.7942178 | R44: 3.6982308 | S44: 3.6046721 | T44: 3.5134803 | U44: 3.4245955 | V44: 3.3379593 | W44: 3.2535149 | X44: 3.1712067 | Y44: 3.0909808 | Z44: 3.0127845 | AA44: 2.9365664 | AB44: 2.8622765 | AD44: 2.789866 | AE44: 2.7192873 | AF44: 2.6504942 | AG44: 2.5834414 | AH44: 2.5180849 | AI44: 2.4543819 | AJ44: 1.7997555 | AK44: 1.7542249 | AL44: 1.7098461 | AM44: 1.66659 | AN44: 1.6244283 | AO44: 1.5833331 | AP44: 1.5432776
A45: Bitcoin per month (Site 90%) | C45: 1.191165 | D45: 1.741546 | E45: 2.2633172 | F45: 2.7575742 | G45: 3.2253749 | H45: 3.6677418 | I45: 4.0856622 | J45: 3.9823022 | K45: 3.881557 | L45: 3.7833606 | M45: 3.6876483 | N45: 3.5943573 | P45: 3.5034264 | Q45: 3.414796 | R45: 3.3284077 | S45: 3.2442049 | T45: 3.1621323 | U45: 3.082136 | V45: 3.0041634 | W45: 2.9281634 | X45: 2.8540861 | Y45: 2.7818828 | Z45: 2.7115061 | AA45: 2.6429098 | AB45: 2.5760489 | AD45: 2.5108794 | AE45: 2.4473586 | AF45: 2.3854448 | AG45: 2.3250973 | AH45: 2.2662764 | AI45: 2.2089437 | AJ45: 1.6197799 | AK45: 1.5788024 | AL45: 1.5388615 | AM45: 1.499931 | AN45: 1.4619854 | AO45: 1.4249998 | AP45: 1.3889498
A46: Monthly Revenue (Site) | C46: 97081.783 | D46: 144602.76 | E46: 191453.33 | F46: 237640.54 | G46: 283171.39 | H46: 328052.8 | I46: 372291.64 | J46: 369684.19 | K46: 367095 | L46: 364523.95 | M46: 361970.9 | N46: 359435.73 | O46: 3477004 | P46: 356918.32 | Q46: 354418.54 | R46: 351936.27 | S46: 349471.38 | T46: 347023.76 | U46: 344593.28 | V46: 342179.82 | W46: 339783.26 | X46: 337403.49 | Y46: 335040.39 | Z46: 332693.84 | AA46: 330363.72 | AB46: 328049.93 | AD46: 325752.33 | AE46: 323470.83 | AF46: 321205.31 | AG46: 318955.66 | AH46: 316721.76 | AI46: 314503.51 | AJ46: 234948.51 | AK46: 233302.98 | AL46: 231668.98 | AM46: 230046.42 | AN46: 228435.22 | AO46: 226835.31 | AP46: 225246.61 | AQ46: 3205341.1
...

Sheet Bitcoin Price Forecast Models
AN8: Forecasted Bitcoin Value (USD)
AM9: 45778 | AN9: 80000
AM10: 45809 | AN10: 81501.541
AM11: 45839 | AN11: 83031.265
AM12: 45870 | AN12: 84589.701
AM13: 45901 | AN13: 86177.388
AM14: 45931 | AN14: 87794.874
AM15: 45962 | AN15: 89442.719
AM16: 45992 | AN16: 91121.493
AM17: 46023 | AN17: 92831.777
AM18: 46054 | AN18: 94574.161
AM19: 46082 | AN19: 96349.248
AM20: 46113 | AN20: 98157.653
... AM29: 46388 | AN29: 116039.72
X30: TON Leverages a conservative model of Bitcoin price to forecast profitability. While popular models forecast Bitcoin prices in excess of 50% year over Year, TON's model requires a steady forecast of Bitcoin price to weather the ups and downs throughout the mining facility lifecycle. The TON model also forecasts mining difficulty which considers the decreased mining revenue of mining machines over time. To reflect this, the network difficulty increases at a faster rate than the Bitcoin price increase. In TON's view of developing project models, a cashflow positive model must be achieved using a conservative Bitcoin price increase model to ensure resiliency for the mining facility through times of increase volatility. TON is able to adjust the model as time progresses to ensure a resilient decision making process including a miner upgrade prior to the Halvening event. TON models, like any other forecast, are based on assumptions and speculation and are not to be taken as actual data. Bitcoin in particular experiences extreme volatility which can quickly cause the model to diverge from reality. External due diligence is required when interpreting and using TON models. | AM30: 46419 | AN30: 118217.7
AM31: 46447 | AN31: 120436.56
AM32: 46478 | AN32: 122697.07
AM33: 46508 | AN33: 125000
AM34: 46539 | AN34: 127346.16
AM35: 46569 | AN35: 129736.35
AM36: 46600 | AN36: 132171.41
AM37: 46631 | AN37: 134652.17
AM38: 46661 | AN38: 137179.49
AM39: 46692 | AN39: 139754.25
AM40: 46722 | AN40: 142377.33
AM41: 46753 | AN41: 145049.65
AM42: 46784 | AN42: 147772.13
... AM47: 46935 | AN47: 162170.44

Sheet Ogboinbiri Project Budget
A1: 1.0 | D1: Obgoinbiri Site | E1: Budget (USD) | F1: Budget (CAD) | G1: USD/CAD | H1: 1.4
B2: 1.1 | D2: Containers | E2: =SUM(E3:E4) -> 160000 | F2: =E2*$H$1 -> 224000
C3: 1.1.1 | D3: 1MW TON Infraflow (with power cables) | E3: 80000 | F3: =E3*$H$1 -> 112000
C4: 1.1.2 | D4: 2MW TON Phase 2 (with power cables) | E4: 80000 | F4: =E4*$H$1 -> 112000
B5: 1.2 | D5: Miners | E5: =SUM(E6:E7) -> 432000 | F5: =E5*$H$1 -> 604800
C6: 1.2.1 | D6: Initial TON Miners | E6: =400*360 -> 144000 | F6: =E6*$H$1 -> 201600
C7: 1.2.2 | D7: TON Phase 2 Miners | E7: =400*720 -> 288000 | F7: =E7*$H$1 -> 403200
B8: 1.3 | D8: Transformers | E8: =SUM(E9:E10) -> 90000 | F8: =E8*$H$1 -> 126000
C9: 1.3.1 | D9: Initial 1.5 MVA Transformer 11KVA-400V | E9: 30000 | F9: =E9*$H$1 -> 42000
C10: 1.3.2 | D10: Phase 2 1.5MVA Transformer 11KVA-400V | E10: =2*30000 -> 60000 | F10: =E10*$H$1 -> 84000
B11: 1.4 | D11: Electrical Materials | E11: =SUM(E12:E13) -> 17000 | F11: =E11*$H$1 -> 23800
C12: 1.4.1 | D12: 1/0 3 wire Cable | E12: 15000 | F12: =E12*$H$1 -> 21000
C13: 1.4.2 | D13: Misc electrical (lugs, bolts, strut) | E13: 2000 | F13: =E13*$H$1 -> 2800
B14: 1.5 | D14: Logistics to Port Harcourt | E14: =SUM(E15:E18) -> 18000 | F14: =E14*$H$1 -> 25200
D15: Ship TON infraflow container | E15: 12000 | F15: =E15*$H$1 -> 16800
D16: Ship Transformer | E16: 2000 | F16: =E16*$H$1 -> 2800
D17: Ship Cable | E17: 2000 | F17: =E17*$H$1 -> 2800
D18: Ship miners | E18: 2000 | F18: =E18*$H$1 -> 2800
B19: 1.6 | D19: Logistics from Port Harcourt to Ogboinbiri | E19: =SUM(E20:E23) -> 5500 | F19: =E19*$H$1 -> 7700
D20: Ship TON infraflow container | E20: 1500 | F20: =E20*$H$1 -> 2100
D21: Ship Transformer | E21: 1000 | F21: =E21*$H$1 -> 1400
D22: Ship Cable | E22: 1000 | F22: =E22*$H$1 -> 1400
D23: Ship miners | E23: 2000 | F23: =E23*$H$1 -> 2800
B24: 1.7 | D24: Construction | E24: =SUM(E25:E28) -> 0 | F24: =E24*$H$1 -> 0
F25: =E25*$H$1 -> 0
F26: =E26*$H$1 -> 0
F27: =E27*$H$1 -> 0
F28: =E28*$H$1 -> 0
F29: =E29*$H$1 -> 0
B30: 1.8 | D30: Equipment for Makir | E30: =SUM(E31:E34) -> 0 | F30: =E30*$H$1 -> 0
F31: =E31*$H$1 -> 0
F32: =E32*$H$1 -> 0
F33: =E33*$H$1 -> 0
F34: =E34*$H$1 -> 0
F35: =E35*$H$1 -> 0

Sheet Site2 Overview
A1: Site 2 - 10 MW Model
D4: Values in USD
A5: # of MW of Power | B5: 3
A6: # of MW Mining | B6: =B7*1.14 -> 3.42 | D6: Capex Per MW
A7: # of Containers | B7: 3 | D7: MW | E7: =B6 -> 3.42
A8: # of Transformers | B8: 3 | D8: Cost per MW | E8: =SUM(B24:B31)/E7 -> 242631.58
F10: Miner Power(W) | G10: 3250
E11: ='Site 2 Cost Model'!A3 -> 80000 | F11: Network TH | G11: 800000000
A12: Container Cost Each | B12: 80000 | D12: Miners | E12: TH | F12: Quantity | G12: Bitcoin per day
A13: Transformer Cost Each | B13: 30000 | D13: S19J Pro | E13: 104 | F13: =B6*1000/(G10/1000) -> 1052.3077 | G13: =(F13*E13)/G11*3.125*6*24*28 -> 1.72368
A14: Distribution Cost Each
A15: Buildout Cost Each Container | B15: 10000
A17: Cashflow | B17: Month 0 | C17: Month 1 | D17: Month 2 | E17: Month 3
A18: Revenue | C18: Startup @ 50%
A19: Bitcoin per month | C19: =$G$13 -> 1.72368 | D19: =$G$13 -> 1.72368 | E19: =$G$13 -> 1.72368
A20: Total Bitcoin | C20: =C19 -> 1.72368 | D20: =C20+D19 -> 3.44736 | E20: =D20+E19 -> 5.17104
A21: Revenue (at 90,000 BTCUSD) | C21: =$E$11*C19 -> 137894.4 | D21: =$E$11*D19 -> 137894.4 | E21: =$E$11*E19 -> 137894.4
A22: Costs
A23: Capex
A24: Container | B24: =B12*B7 -> 240000
A25: Construction | B25: =B7*B15 -> 30000
A26: Miners | B26: =360*B7*400 -> 432000
A27: Transformers | B27: =B13*B8 -> 90000
A28: Site Development Management | B28: 10000
A29: Land fee (per year) | B29: 5000
A30: One time land startup fee | B30: 3000
A31: Barge cost (Assume 1 per container) | B31: =6600*(B7) -> 19800
A32: CapEx Total | B32: =SUM(B24:B31) -> 829800
A34: OpEx
A35: Site Operations | C35: 9000 | D35: 9000 | E35: 9000
A36: OpEx Total | C36: =SUM(C35:C35) -> 9000 | D36: =SUM(D35:D35) -> 9000 | E36: =SUM(E35:E35) -> 9000

Sheet Site 2 Cost Model
A2: Assumed BTCUSD
A3: 80000
A4: Assumed network hashrate(PH)
A5: 850000
A7: Container Cost Each | B7: ='Site2 Overview'!B12 -> 80000
A8: Transformer Cost Each | B8: ='Site2 Overview'!B13 -> 30000
A9: Buildout Cost Each | B9: ='Site2 Overview'!B15 -> 10000 | C9: TH | D9: W
A10: Miners | B10: 460 | C10: 104 | D10: 3250
B11: 45717 | C11: 45748 | D11: 45778 | E11: 45809 | F11: 45839 | G11: 45870 | H11: 45901 | I11: 45931 | J11: 45962 | K11: 45992 | L11: 46023 | M11: 46054 | N11: 46082
A12: New Infrastructure count | B12: Month 0 | C12: Month 1 | D12: Month 2 | E12: Month 3 | F12: Month 4 | G12: Month 5 | H12: Month 6 | I12: Month 7 | J12: Month 8 | K12: Month 9 | L12: Month 10 | M12: Month 11 | N12: Month 12 | O12: Year1
A13: New Containers | B13: 1 | E13: 3
A14: New miners | B14: 360 | E14: 1080
A15: New Transformers | B15: 1 | E15: 3
A16: Total Infrastructure Count | B16: Month 0 | C16: Month 1 | D16: Month 2 | E16: Month 3 | F16: Month 4 | G16: Month 5 | H16: Month 6 | I16: Month 7 | J16: Month 8 | K16: Month 9 | L16: Month 10 | M16: Month 11 | N16: Month 12
A17: Containers | B17: =B13 -> 1 | C17: =B17+C13 -> 1 | D17: =C17+D13 -> 1 | E17: =E13 -> 3 | F17: =E17+F13 -> 3 | G17: =F17+G13 -> 3 | H17: =G17+H13 -> 3 | I17: =H17+I13 -> 3 | J17: =I17+J13 -> 3 | K17: =J17+K13 -> 3 | L17: =K17+L13 -> 3 | M17: =L17+M13 -> 3 | N17: =M17+N13 -> 3
A18: Miners Total | B18: =B14 -> 360 | C18: =B18+C14 -> 360 | D18: =C18+D14 -> 360 | E18: =E14 -> 1080 | F18: 924 | G18: =F18+G14 -> 924 | H18: =G18+H14 -> 924 | I18: =H18+I14 -> 924 | J18: =I18+J14 -> 924 | K18: =J18+K14 -> 924 | L18: =K18+L14 -> 924 | M18: =L18+M14 -> 924 | N18: =M18+N14 -> 924
A19: Transformers | B19: =B15 -> 1 | C19: =B19+C15 -> 1 | D19: =C19+D15 -> 1 | E19: =E15 -> 3 | F19: =E19+F15 -> 3 | G19: =F19+G15 -> 3 | H19: =G19+H15 -> 3 | I19: =H19+I15 -> 3 | J19: =I19+J15 -> 3 | K19: =J19+K15 -> 3 | L19: =K19+L15 -> 3 | M19: =L19+M15 -> 3 | N19: =M19+N15 -> 3
A20: Site Power (MW) | B20: =B18*$D$10/1000/1000 -> 1.17 | C20: =C18*$D$10/1000/1000 -> 1.17 | D20: =D18*$D$10/1000/1000 -> 1.17 | E20: =E18*$D$10/1000/1000 -> 3.51 | F20: =F18*$D$10/1000/1000 -> 3.003 | G20: =G18*$D$10/1000/1000 -> 3.003 | H20: =H18*$D$10/1000/1000 -> 3.003 | I20: =I18*$D$10/1000/1000 -> 3.003 | ... N20: =N18*$D$10/1000/1000 -> 3.003
A21: Hashing Online Total Site (PH) | B21: =B18*$C$10/1000 -> 37.44 | C21: =C18*$C$10/1000 -> 37.44 | D21: =D18*$C$10/1000 -> 37.44 | E21: =E18*$C$10/1000 -> 112.32 | F21: =((F18)*$C$10/1000) -> 96.096 | G21: =((G18)*$C$10/1000) -> 96.096 | H21: =((H18)*$C$10/1000) -> 96.096 | I21: =((I18)*$C$10/1000) -> 96.096 | J21: =((J18)*$C$10/1000) -> 96.096 | K21: =((K18)*$C$10/1000) -> 96.096 | L21: =((L18)*$C$10/1000) -> 96.096 | M21: =((M18)*$C$10/1000) -> 96.096 | N21: =((N18)*$C$10/1000) -> 96.096
A22: Hashing Online TON (PH) | B22: =B18*$C$10/1000 -> 37.44 | C22: =C18*$C$10/1000 -> 37.44 | D22: =D18*$C$10/1000 -> 37.44 | E22: =E18*$C$10/1000 -> 112.32 | F22: =F18*$C$10/1000 -> 96.096 | G22: =G18*$C$10/1000 -> 96.096 | H22: =H18*$C$10/1000 -> 96.096 | I22: =I18*$C$10/1000 -> 96.096 | ... N22: =N18*$C$10/1000 -> 96.096
A24: Cashflow | B24: Month 0 | C24: Month 1 | D24: Month 2 | E24: Month 3 | F24: Month 4 | G24: Month 5 | H24: Month 6 | I24: Month 7 | J24: Month 8 | K24: Month 9 | L24: Month 10 | M24: Month 11 | N24: Month 12
A25: Costs
A26: Capex
A27: Container | B27: =B13*$B$7 -> 80000 | C27: =C13*$B$7 -> 0 | D27: =D13*$B$7 -> 0 | E27: =E13*$B$7 -> 240000 | F27: =F13*$B$7 -> 0 | G27: =G13*$B$7 -> 0 | H27: =H13*$B$7 -> 0 | I27: =I13*$B$7 -> 0 | ... N27: =N13*$B$7 -> 0 | O27: =SUM(B27:N27) -> 320000
A28: Miners | B28: =B14*$B$10 -> 165600 | C28: =C14*$B$10 -> 0 | D28: =D14*$B$10 -> 0 | E28: =E14*$B$10 -> 496800 | F28: =F14*$B$10 -> 0 | G28: =G14*$B$10 -> 0 | H28: =H14*$B$10 -> 0 | I28: =I14*$B$10 -> 0 | ... N28: =N14*$B$10 -> 0 | O28: =SUM(B28:N28) -> 662400
A29: Transformers | B29: =$B$8*B15 -> 30000 | C29: =$B$8*C15 -> 0 | D29: =$B$8*D15 -> 0 | E29: =$B$8*E15 -> 90000 | F29: =$B$8*F15 -> 0 | G29: =$B$8*G15 -> 0 | H29: =$B$8*H15 -> 0 | I29: =$B$8*I15 -> 0 | ... N29: =$B$8*N15 -> 0 | O29: =SUM(B29:N29) -> 120000
A30: Construction | B30: =($B$9+6600)*B13 -> 16600 | C30: =($B$9+6600)*C13 -> 0 | D30: =($B$9+6600)*D13 -> 0 | E30: 20000 | F30: =($B$9+6600)*F13 -> 0 | G30: =($B$9+6600)*G13 -> 0 | H30: =($B$9+6600)*H13 -> 0 | I30: =($B$9+6600)*I13 -> 0 | J30: =($B$9+6600)*J13 -> 0 | K30: =($B$9+6600)*K13 -> 0 | L30: =($B$9+6600)*L13 -> 0 | M30: =($B$9+6600)*M13 -> 0 | N30: =($B$9+6600)*N13 -> 0 | O30: =SUM(B30:N30) -> 36600
A31: Site Development Management | B31: 10000 | C31: 0 | D31: 0 | E31: 0 | F31: 0 | G31: 0 | H31: 0 | I31: 0 | K31: 0 | L31: 0 | M31: 0 | N31: 0 | O31: =SUM(B31:N31) -> 10000
A32: Site Startup Costs | B32: 8000 | C32: 0 | D32: 0 | E32: 0 | F32: 0 | G32: 0 | H32: 0 | I32: 0 | J32: 0 | K32: 0 | L32: 0 | M32: 0 | N32: 0 | O32: =SUM(B32:N32) -> 8000
A33: TON TRAVEL | B33: 30000 | E33: 30000 | H33: 30000
A34: Africa Customs and Logistics | B34: 50000 | E34: 75000 | G34: 30000
A35: Power cost upfront | B35: =E47*2 -> 67931.136
A36: CapEx Total | B36: =SUM(B27:B35) -> 458131.14 | C36: =SUM(C27:C32) -> 0 | D36: =SUM(D27:D32) -> 0 | E36: =SUM(E27:E34) -> 951800 | F36: =SUM(F27:F32) -> 0 | G36: =SUM(G27:G34) -> 30000 | H36: =SUM(H27:H33) -> 30000 | I36: =SUM(I27:I32) -> 0 | J36: =SUM(J27:J32) -> 0 | K36: =SUM(K27:K32) -> 0 | L36: =SUM(L27:L32) -> 0 | M36: =SUM(M27:M32) -> 0 | N36: =SUM(N27:N32) -> 0 | O36: =SUM(O27:O32) -> 1157000
A38: OpEx
A39: Site Operations | H39: =#REF! -> #REF! | I39: =#REF! -> #REF! | J39: =#REF! -> #REF! | K39: =#REF! -> #REF! | L39: =#REF! -> #REF! | M39: =#REF! -> #REF! | N39: =#REF! -> #REF! | O39: =SUM(B39:N39) -> #REF!
A40: OpEx Total | B40: =SUM(B39:B39) -> 0 | C40: =SUM(C39:C39) -> 0 | D40: =SUM(D39:D39) -> 0 | E40: =SUM(E39:E39) -> 0 | F40: =SUM(F39:F39) -> 0 | G40: =SUM(G39:G39) -> 0 | H40: =SUM(H39:H39) -> #REF! | I40: =SUM(I39:I39) -> #REF! | ... N40: =SUM(N39:N39) -> #REF! | O40: =SUM(#REF!) -> #REF!
A41: Revenue
A42: Bitcoin per month | C42: =C21/$A$5*3.125*6*24*28 -> 0.55499294 | D42: =D21/$A$5*3.125*6*24*28 -> 0.55499294 | E42: =E21/$A$5*3.125*6*24*28 -> 1.6649788 | F42: =F21/$A$5*3.125*6*24*28 -> 1.4244819 | G42: =G21/$A$5*3.125*6*24*28 -> 1.4244819 | H42: =H21/$A$5*3.125*6*24*28 -> 1.4244819 | I42: =I21/$A$5*3.125*6*24*28 -> 1.4244819 | J42: =J21/$A$5*3.125*6*24*28 -> 1.4244819 | ... N42: =N21/$A$5*3.125*6*24*28 -> 1.4244819 | O42: =SUM(B42:N42) -> 15.595302
A43: Bitcoin per month (TON) | C43: =C42*0.85 -> 0.471744 | D43: =D42*0.85 -> 0.471744 | E43: =E42*0.85 -> 1.415232 | F43: =F42*0.85 -> 1.2108096 | G43: =G42*0.85 -> 1.2108096 | H43: =H42*0.85 -> 1.2108096 | I43: =I42*0.85 -> 1.2108096 | J43: =J42*0.85 -> 1.2108096 | ... N43: =N42*0.85 -> 1.2108096 | O43: =SUM(B43:N43) -> 13.256006
A44: Monthly Revenue (TON) | C44: =C43*$A$3 -> 37739.52 | D44: =D43*$A$3 -> 37739.52 | E44: =E43*$A$3 -> 113218.56 | F44: =F42*$A$3 -> 113958.55 | G44: =G43*$A$3 -> 96864.768 | H44: =H43*$A$3 -> 96864.768 | I44: =I43*$A$3 -> 96864.768 | J44: =J43*$A$3 -> 96864.768 | K44: =K43*$A$3 -> 96864.768 | L44: =L43*$A$3 -> 96864.768 | M44: =M43*$A$3 -> 96864.768 | N44: =N43*$A$3 -> 96864.768 | O44: =SUM(C44:N44) -> 1077574.3
...

Sheet Site 2 Project Budget
A1: 1.0 | D1: Obgoinbiri Site | E1: Budget (USD) | F1: Budget (CAD) | G1: USD/CAD | H1: 1.4
B2: 1.1 | D2: Containers | E2: =SUM(E3:E3) -> 240000 | F2: =E2*$H$1 -> 336000
C3: 1.1.1 | D3: TON Infraflow (with power cables) | E3: ='Site2 Overview'!B24 -> 240000 | F3: =E3*$H$1 -> 336000
B4: 1.2 | D4: Miners | E4: =SUM(E5:E5) -> 432000 | F4: =E4*$H$1 -> 604800
C5: 1.2.1 | D5: TON Miners | E5: ='Site2 Overview'!B26 -> 432000 | F5: =E5*$H$1 -> 604800
B6: 1.3 | D6: Transformers | E6: =SUM(E7:E7) -> 90000 | F6: =E6*$H$1 -> 126000
C7: 1.3.1 | D7: 1.5 MVA Transformer 11KVA-400V | E7: ='Site2 Overview'!B27 -> 90000 | F7: =E7*$H$1 -> 126000
B8: 1.4 | D8: Electrical Materials | E8: =SUM(E9:E10) -> 70000 | F8: =E8*$H$1 -> 98000
C9: 1.4.1 | D9: 1/0 3 wire Cable | E9: =12000*5 -> 60000 | F9: =E9*$H$1 -> 84000
C10: 1.4.2 | D10: Misc electrical (lugs, bolts, strut) | E10: =2000*5 -> 10000 | F10: =E10*$H$1 -> 14000
B11: 1.5 | D11: Logistics to Port Harcourt | E11: =SUM(E12:E15) -> 18000 | F11: =E11*$H$1 -> 25200
D12: Ship TON infraflow container | E12: 12000 | F12: =E12*$H$1 -> 16800
D13: Ship Transformer | E13: 2000 | F13: =E13*$H$1 -> 2800
D14: Ship Cable | E14: 2000 | F14: =E14*$H$1 -> 2800
D15: Ship miners | E15: 2000 | F15: =E15*$H$1 -> 2800
B16: 1.6 | D16: Logistics from Port Harcourt to Ogboinbiri | E16: =SUM(E17:E20) -> 5500 | F16: =E16*$H$1 -> 7700
D17: Ship TON infraflow container | E17: 1500 | F17: =E17*$H$1 -> 2100
D18: Ship Transformer | E18: 1000 | F18: =E18*$H$1 -> 1400
D19: Ship Cable | E19: 1000 | F19: =E19*$H$1 -> 1400
D20: Ship miners | E20: 2000 | F20: =E20*$H$1 -> 2800
B21: 1.7 | D21: Construction | E21: =SUM(E22:E25) -> 0 | F21: =E21*$H$1 -> 0
F22: =E22*$H$1 -> 0
F23: =E23*$H$1 -> 0
F24: =E24*$H$1 -> 0
F25: =E25*$H$1 -> 0
F26: =E26*$H$1 -> 0
B27: 1.8 | D27: Equipment for Makir | E27: =SUM(E28:E31) -> 0 | F27: =E27*$H$1 -> 0
F28: =E28*$H$1 -> 0
F29: =E29*$H$1 -> 0
F30: =E30*$H$1 -> 0
F31: =E31*$H$1 -> 0
F32: =E32*$H$1 -> 0
